Workbook
Name RETEICAJULIO2025: retICA7[#All]
Name Tretefjulio2025: retfuente4[#All]

Sheet Proveedores
A1: NUMERO | B1: NOMBRE | C1: NIT
A2: 1 | B2: SISCONT LIMITADA | C2: 814000143-8
A3: 2 | B3: EL CONSTRUCTOR | C3: 1124848579
A4: 3 | B4: LB GROUP SAS | C4: 900698138-8
A5: 4 | B5: COINSER LTDA | C5: 846000005-6
A6: 5 | B6: ACEROS DUVAN | C6: 1126456991

Sheet Certificado
B1: RETENCION EN LA FUENTE
B2: Nombre | C2: EL CONSTRUCTOR | D2: AÑO | E2: 2024
B4: CONCEPTO | C4: BASE GRAVABLE | D4: TARIFA | E4: VALOR RETENIDO
B5: Compras | C5: =SUMIFS(#REF!,#REF!,Certificado!$C$2,#REF!,"APLICA",#REF!,"2,50%") -> #REF! | D5: ='ret. fuente 2025 enero junio'!D2 -> 0.025 | E5: =SUMIFS(#REF!,#REF!,Certificado!$C$2,#REF!,"APLICA",#REF!,"2,50%") -> #REF!
B6: Servicios | C6: =SUMIFS(#REF!,#REF!,Certificado!$C$2,#REF!,"APLICA",#REF!,"1%") -> #REF! | D6: ='ret. fuente 2025 enero junio'!D19 -> 0.01 | E6: =SUMIFS(#REF!,#REF!,Certificado!$C$2,#REF!,"APLICA",#REF!,"1%") -> #REF!
B8: RETEICA
B10: CONCEPTO | C10: BASE GRAVABLE | D10: TARIFA | E10: VALOR RETENIDO
B11: Compras | C11: =SUMIFS(#REF!,#REF!,Certificado!$C$2,#REF!,"APLICA",#REF!,"0,50%") -> #REF! | D11: ='ret. ICA 2025 enero junio'!D2 -> 0.006 | E11: =SUMIFS(#REF!,#REF!,Certificado!$C$2,#REF!,"APLICA",#REF!,"0,50%") -> #REF!
B12: Servicios | C12: =SUMIFS(#REF!,#REF!,Certificado!$C$2,#REF!,"APLICA",#REF!,"1%") -> #REF! | D12: ='ret. ICA 2025 enero junio'!D3 -> 0.01 | E12: =SUMIFS(#REF!,#REF!,Certificado!$C$2,#REF!,"APLICA",#REF!,"1%") -> #REF!
G14: CHEQUEO
E15: =SUM(E12+E11+E6+E5) -> #REF! | G15: =#REF! -> #REF!

Sheet ret. fuente 2025 JULIO 
A1: conceptos de retención | B1: Base mínima en UVT | C1: Base mínima en pesos | D1: Tarifa de retención. | F1: VALOR UVT
A2: Compras generales (declarantes) | B2: 27 | C2: 498000 | D2: 0.025 | F2: 49799
A3: Compras generales (no declarantes) | B3: 27 | C3: 498000 | D3: 0.035
A4: Compras con tarjeta débito o crédito | B4: 0 | C4: =retfuente4[[#This Row],[Base mínima en UVT]]*$F$2 -> 0 | D4: 0.015
A5: Compras de bienes o productos agrícolas o pecuarios sin procesamiento industrial | B5: 92 | C5: =retfuente4[[#This Row],[Base mínima en UVT]]*$F$2 -> 4581508 | D5: 0.015
A6: Compras de bienes o productos agrícolas o pecuarios con procesamiento industrial (declarantes) | B6: 27 | C6: =retfuente4[[#This Row],[Base mínima en UVT]]*$F$2 -> 1344573 | D6: 0.025
A7: Compras de bienes o productos agrícolas o pecuarios con procesamiento industrial declarantes (no declarantes) | B7: 27 | C7: =retfuente4[[#This Row],[Base mínima en UVT]]*$F$2 -> 1344573 | D7: 0.035
A8: Compras de café pergamino o cereza | B8: 160 | C8: =retfuente4[[#This Row],[Base mínima en UVT]]*$F$2 -> 7967840 | D8: 0.005
A9: Compras de combustibles derivados del petróleo | B9: 0 | C9: =retfuente4[[#This Row],[Base mínima en UVT]]*$F$2 -> 0 | D9: 0.001
A10: Enajenación de activos fijos de personas naturales (notarías y tránsito son agentes retenedores) | B10: 0 | C10: =retfuente4[[#This Row],[Base mínima en UVT]]*$F$2 -> 0 | D10: 0.01
A11: Compras de vehículos | B11: 0 | C11: =retfuente4[[#This Row],[Base mínima en UVT]]*$F$2 -> 0 | D11: 0.01
A12: Compras de bienes raíces cuya destinación y uso sea vivienda de habitación (por las primeras 20.000 UVT, es decir hasta $941.300.000) | B12: 0 | C12: =retfuente4[[#This Row],[Base mínima en UVT]]*$F$2 -> 0 | D12: 0.01
A13: Compras de bienes raíces cuya destinación y uso sea vivienda de habitación (exceso de las primeras 20.000 UVT, es decir superior a $941.300.000) | B13: 20000 | C13: =retfuente4[[#This Row],[Base mínima en UVT]]*$F$2 -> 995980000 | D13: 0.025
A14: Compras de bienes raíces cuya destinación y uso sea distinto a vivienda de habitación | B14: 0 | C14: =retfuente4[[#This Row],[Base mínima en UVT]]*$F$2 -> 0 | D14: 0.025
A15: Servicios generales (declarantes) | B15: 4 | C15: 100000 | D15: 0.04
A16: Servicios generales (no declarantes) | B16: 4 | C16: 100000 | D16: 0.06
A17: Por emolumentos eclesiásticos (declarantes) | B17: 27 | C17: =retfuente4[[#This Row],[Base mínima en UVT]]*$F$2 -> 1344573 | D17: 0.04
A18: Por emolumentos eclesiásticos (no declarantes) | B18: 27 | C18: =retfuente4[[#This Row],[Base mínima en UVT]]*$F$2 -> 1344573 | D18: 0.035
A19: Servicios de transporte de carga | B19: 4 | C19: =retfuente4[[#This Row],[Base mínima en UVT]]*$F$2 -> 199196 | D19: 0.01
A20: Servicios de transporte nacional de pasajeros por vía terrestre (declarantes) | B20: 27 | C20: =retfuente4[[#This Row],[Base mínima en UVT]]*$F$2 -> 1344573 | D20: 0.035
A21: Servicios de transporte nacional de pasajeros por vía terrestre (no declarantes) | B21: 27 | C21: =retfuente4[[#This Row],[Base mínima en UVT]]*$F$2 -> 1344573 | D21: 0.035
A22: Servicios de transporte nacional de pasajeros por vía aérea o marítima | B22: 4 | C22: =retfuente4[[#This Row],[Base mínima en UVT]]*$F$2 -> 199196 | D22: 0.01
A23: Servicios prestados por empresas de servicios temporales (sobre AIU) | B23: 4 | C23: =retfuente4[[#This Row],[Base mínima en UVT]]*$F$2 -> 199196 | D23: 0.01
A24: Servicios prestados por empresas de vigilancia y aseo (sobre AIU) | B24: 4 | C24: =retfuente4[[#This Row],[Base mínima en UVT]]*$F$2 -> 199196 | D24: 0.02
A25: Servicios integrales de salud prestados por IPS | B25: 4 | C25: =retfuente4[[#This Row],[Base mínima en UVT]]*$F$2 -> 199196 | D25: 0.02
A26: Servicios de hoteles y restaurantes (declarantes) | B26: 4 | C26: =retfuente4[[#This Row],[Base mínima en UVT]]*$F$2 -> 199196 | D26: 0.035
A27: Servicios de hoteles y restaurantes (no declarantes) | B27: 4 | C27: =retfuente4[[#This Row],[Base mínima en UVT]]*$F$2 -> 199196 | D27: 0.035
A28: Arrendamiento de bienes muebles | B28: 0 | C28: =retfuente4[[#This Row],[Base mínima en UVT]]*$F$2 -> 0 | D28: 0.04
... A43: Retención en la fuente por Iva en compras | B43: 27 | C43: =retfuente4[[#This Row],[Base mínima en UVT]]*$F$2 -> 1344573 | D43: 0.15
A44: RETENCIÓN POR PAGOS AL EXTERIOR
A45: Pagos o abonos en cuenta por concepto de intereses, comisiones, honorarios, regalías, arrendamientos, compensaciones por servicios personales, o explotación de toda especie de propiedad industrial o del know-how, prestación de servicios, beneficios o regalías provenientes de la propiedad literaria, artística y científica, explotación de películas cinematográficas y explotación de software. | B45: 0 | C45: =retfuente4[[#This Row],[Base mínima en UVT]]*$F$2 -> 0 | D45: 0.2
A46: Pagos o abonos en cuenta por concepto de consultorías, servicios técnicos y de asistencia técnica, prestados por personas no residentes o no domiciliadas en Colombia, | B46: 0 | C46: =retfuente4[[#This Row],[Base mínima en UVT]]*$F$2 -> 0 | D46: 0.2
A47: Pagos o abonos en cuenta por concepto de rendimientos financieros, realizados a personas no residentes o no domiciliadas en el país, originados en créditos obtenidos en el exterior por término igual o superior a un (1) año o por concepto de intereses o costos financieros del canon de arrendamiento originados en contratos de leasing que se celebre directamente o a través de compañías de leasing con empresas extranjeras sin domicilio en Colombia, | B47: 0 | C47: =retfuente4[[#This Row],[Base mínima en UVT]]*$F$2 -> 0 | D47: 0.15
A48: Pagos o abonos en cuenta, originados en contratos de leasing sobre naves, helicópteros y/o aerodinos, así como sus partes que se celebren directamente o a través de compañías de leasing, con empresas extranjeras sin domicilio en Colombia. | B48: 0 | C48: =retfuente4[[#This Row],[Base mínima en UVT]]*$F$2 -> 0 | D48: 0.01
A49: Pagos o abonos en cuenta por concepto de rendimientos financieros o intereses, realizados a personas no residentes o no domiciliadas en el país, originados en créditos o valores de contenido crediticio, por término igual o superior a ocho (8) años, destinados a la financiación de proyectos de infraestructura bajo el esquema de Asociaciones Público-Privadas en el marco de la Ley 1508 de 2012. | B49: 0 | C49: =retfuente4[[#This Row],[Base mínima en UVT]]*$F$2 -> 0 | D49: 0.05
A50: Pagos o abonos en cuenta por concepto de prima cedida por reaseguros realizados a personas no residentes o no domiciliadas en el país. | B50: 0 | C50: =retfuente4[[#This Row],[Base mínima en UVT]]*$F$2 -> 0 | D50: 0.01
A51: Pagos o abono en cuenta por concepto de administración o dirección de que trata el artículo 124 del estatuto tributario, realizados a personas no residentes o no domiciliadas en el país. | B51: 0 | C51: =retfuente4[[#This Row],[Base mínima en UVT]]*$F$2 -> 0 | D51: 0.33

Sheet ret. ICA 2025 JULIO
A1: conceptos de retención | B1: Base mínima en UVT | C1: Base mínima en pesos | D1: Tarifa de retención.
A2: compras | B2: 10 | C2: 498000 | D2: 0.006
A3: servicios | B3: 10 | C3: 498000 | D3: 0.01

Sheet ret. fuente 2025 enero junio
A1: conceptos de retención | B1: Base mínima en UVT | C1: Base mínima en pesos | D1: Tarifa de retención. | F1: VALOR UVT
A2: Compras generales (declarantes) | B2: 27 | C2: =retfuente[[#This Row],[Base mínima en UVT]]*$F$2 -> 1344573 | D2: 0.025 | F2: 49799
A3: Compras generales (no declarantes) | B3: 27 | C3: =retfuente[[#This Row],[Base mínima en UVT]]*$F$2 -> 1344573 | D3: 0.035
A4: Compras con tarjeta débito o crédito | B4: 0 | C4: =retfuente[[#This Row],[Base mínima en UVT]]*$F$2 -> 0 | D4: 0.015
A5: Compras de bienes o productos agrícolas o pecuarios sin procesamiento industrial | B5: 92 | C5: =retfuente[[#This Row],[Base mínima en UVT]]*$F$2 -> 4581508 | D5: 0.015
A6: Compras de bienes o productos agrícolas o pecuarios con procesamiento industrial (declarantes) | B6: 27 | C6: =retfuente[[#This Row],[Base mínima en UVT]]*$F$2 -> 1344573 | D6: 0.025
A7: Compras de bienes o productos agrícolas o pecuarios con procesamiento industrial declarantes (no declarantes) | B7: 27 | C7: =retfuente[[#This Row],[Base mínima en UVT]]*$F$2 -> 1344573 | D7: 0.035
A8: Compras de café pergamino o cereza | B8: 160 | C8: =retfuente[[#This Row],[Base mínima en UVT]]*$F$2 -> 7967840 | D8: 0.005
A9: Compras de combustibles derivados del petróleo | B9: 0 | C9: =retfuente[[#This Row],[Base mínima en UVT]]*$F$2 -> 0 | D9: 0.001
A10: Enajenación de activos fijos de personas naturales (notarías y tránsito son agentes retenedores) | B10: 0 | C10: =retfuente[[#This Row],[Base mínima en UVT]]*$F$2 -> 0 | D10: 0.01
A11: Compras de vehículos | B11: 0 | C11: =retfuente[[#This Row],[Base mínima en UVT]]*$F$2 -> 0 | D11: 0.01
A12: Compras de bienes raíces cuya destinación y uso sea vivienda de habitación (por las primeras 20.000 UVT, es decir hasta $941.300.000) | B12: 0 | C12: =retfuente[[#This Row],[Base mínima en UVT]]*$F$2 -> 0 | D12: 0.01
A13: Compras de bienes raíces cuya destinación y uso sea vivienda de habitación (exceso de las primeras 20.000 UVT, es decir superior a $941.300.000) | B13: 20000 | C13: =retfuente[[#This Row],[Base mínima en UVT]]*$F$2 -> 995980000 | D13: 0.025
A14: Compras de bienes raíces cuya destinación y uso sea distinto a vivienda de habitación | B14: 0 | C14: =retfuente[[#This Row],[Base mínima en UVT]]*$F$2 -> 0 | D14: 0.025
... A43: Retención en la fuente por Iva en compras | B43: 27 | C43: =retfuente[[#This Row],[Base mínima en UVT]]*$F$2 -> 1344573 | D43: 0.15
A44: RETENCIÓN POR PAGOS AL EXTERIOR
A45: Pagos o abonos en cuenta por concepto de intereses, comisiones, honorarios, regalías, arrendamientos, compensaciones por servicios personales, o explotación de toda especie de propiedad industrial o del know-how, prestación de servicios, beneficios o regalías provenientes de la propiedad literaria, artística y científica, explotación de películas cinematográficas y explotación de software. | B45: 0 | C45: =retfuente[[#This Row],[Base mínima en UVT]]*$F$2 -> 0 | D45: 0.2
A46: Pagos o abonos en cuenta por concepto de consultorías, servicios técnicos y de asistencia técnica, prestados por personas no residentes o no domiciliadas en Colombia, | B46: 0 | C46: =retfuente[[#This Row],[Base mínima en UVT]]*$F$2 -> 0 | D46: 0.2
A47: Pagos o abonos en cuenta por concepto de rendimientos financieros, realizados a personas no residentes o no domiciliadas en el país, originados en créditos obtenidos en el exterior por término igual o superior a un (1) año o por concepto de intereses o costos financieros del canon de arrendamiento originados en contratos de leasing que se celebre directamente o a través de compañías de leasing con empresas extranjeras sin domicilio en Colombia, | B47: 0 | C47: =retfuente[[#This Row],[Base mínima en UVT]]*$F$2 -> 0 | D47: 0.15
A48: Pagos o abonos en cuenta, originados en contratos de leasing sobre naves, helicópteros y/o aerodinos, así como sus partes que se celebren directamente o a través de compañías de leasing, con empresas extranjeras sin domicilio en Colombia. | B48: 0 | C48: =retfuente[[#This Row],[Base mínima en UVT]]*$F$2 -> 0 | D48: 0.01
A49: Pagos o abonos en cuenta por concepto de rendimientos financieros o intereses, realizados a personas no residentes o no domiciliadas en el país, originados en créditos o valores de contenido crediticio, por término igual o superior a ocho (8) años, destinados a la financiación de proyectos de infraestructura bajo el esquema de Asociaciones Público-Privadas en el marco de la Ley 1508 de 2012. | B49: 0 | C49: =retfuente[[#This Row],[Base mínima en UVT]]*$F$2 -> 0 | D49: 0.05
A50: Pagos o abonos en cuenta por concepto de prima cedida por reaseguros realizados a personas no residentes o no domiciliadas en el país. | B50: 0 | C50: =retfuente[[#This Row],[Base mínima en UVT]]*$F$2 -> 0 | D50: 0.01
A51: Pagos o abono en cuenta por concepto de administración o dirección de que trata el artículo 124 del estatuto tributario, realizados a personas no residentes o no domiciliadas en el país. | B51: 0 | C51: =retfuente[[#This Row],[Base mínima en UVT]]*$F$2 -> 0 | D51: 0.33

Sheet ret. ICA 2025 enero junio
A1: conceptos de retención | B1: Base mínima en UVT | C1: Base mínima en pesos | D1: Tarifa de retención.
A2: compras | B2: 10 | C2: 471000 | D2: 0.006
A3: servicios | B3: 10 | C3: 471000 | D3: 0.01

Sheet RETENCION 2025
M1: TOTAL MES | R1: TOTAL MES | S1: TOTAL
F2: AÑO | G2: 2025 | I2: valor minimo de Ret. Fuente | M2: =Tabla36[[#Totals],[VALOR DE RETENCION]] -> 5355514.7 | N2: valor minimo de Ret. ICA | P2: 471000 | R2: =Tabla36[[#Totals],[VALOR DE RETE ICA]] -> 1349193.9 | S2: =R2+M2 -> 6704708.6
I3: valor minimo de Ret. Fuente junio 2025 | K3: 498000 | N3: valor minimo de Ret. Fuente junio 2025 | P3: 498000
I4: RETENCION EN LA FUENTE | N4: RETE ICA
B5: NOMBRE | C5: NIT | D5: Obra | E5: FECHA | F5: Nro factura | G5: Monto Factura | H5: Base Imponible | I5: Concepto | J5: VALOR MINIMO RETEFUENTE | K5: RETE FUENTE ? | L5: % de retencion | M5: VALOR DE RETENCION | N5: Concepto2 | O5: VALOR MINIMO RETE ICA | P5: RETE ICA? | Q5: % De Retencion2 | R5: VALOR DE RETE ICA | S5: Monto a cancelar en Caja | T5: Columna4 | U5: Impuesto por factura
B6: EL CONSTRUCTOR | C6: 1124848579 | D6: OLIMPICO | E6: 45750 | F6: 109314 | G6: 2334600 | H6: 1961849 | I6: Compras generales (declarantes) | J6: =VLOOKUP(I6,retfuente[],3,FALSE) -> 1344573 | K6: =IF(J6>=H6,"NO APLICA","APLICA") -> APLICA | L6: =VLOOKUP(I6,retfuente[],4,FALSE) -> 0.025 | M6: =IF(K6="APLICA",H6*L6,0) -> 49046.225 | N6: compras | O6: =VLOOKUP(N6,retICA[],3,FALSE) -> 471000 | P6: =IF($P$2>=H6,"NO APLICA","APLICA") -> APLICA | Q6: =VLOOKUP(N6,retICA[],4,FALSE) -> 0.006 | R6: =IF(P6="APLICA",H6*Q6,0) -> 11771.094 | S6: =G6-(R6+M6) -> 2273782.7 | U6: =G6-S6 -> 60817.319
B7: LB GROUP SAS | C7: 900698138-8 | D7: OLIMPICO | E7: 45768 | F7: LB2345 | G7: 5002800 | H7: 4204033.6 | I7: Compras generales (declarantes) | J7: =VLOOKUP(I7,retfuente[],3,FALSE) -> 1344573 | K7: =IF(J7>=H7,"NO APLICA","APLICA") -> APLICA | L7: =VLOOKUP(I7,retfuente[],4,FALSE) -> 0.025 | M7: =IF(K7="APLICA",H7*L7,0) -> 105100.84 | N7: compras | O7: =VLOOKUP(N7,retICA[],3,FALSE) -> 471000 | P7: =IF($P$2>=H7,"NO APLICA","APLICA") -> APLICA | Q7: =VLOOKUP(N7,retICA[],4,FALSE) -> 0.006 | R7: =IF(P7="APLICA",H7*Q7,0) -> 25224.202 | S7: =G7-(R7+M7) -> 4872475 | U7: =G7-S7 -> 130325.04
B8: COINSER LTDA | C8: 846000005-6 | D8: OLIMPICO | E8: 45770 | F8: 12807 | G8: 910000 | H8: 767227 | I8: Compras generales (declarantes) | J8: =VLOOKUP(I8,retfuente[],3,FALSE) -> 1344573 | K8: =IF(J8>=H8,"NO APLICA","APLICA") -> NO APLICA | L8: =VLOOKUP(I8,retfuente[],4,FALSE) -> 0.025 | M8: =IF(K8="APLICA",H8*L8,0) -> 0 | N8: compras | O8: =VLOOKUP(N8,retICA[],3,FALSE) -> 471000 | P8: =IF($P$2>=H8,"NO APLICA","APLICA") -> APLICA | Q8: =VLOOKUP(N8,retICA[],4,FALSE) -> 0.006 | R8: =IF(P8="APLICA",H8*Q8,0) -> 4603.362 | S8: =G8-(R8+M8) -> 905396.64 | U8: =G8-S8 -> 4603.362
B9: EL CONSTRUCTOR | C9: 1124848579 | D9: OLIMPICO | E9: 45755 | F9: 110490 | G9: 364400 | H9: 306218 | I9: Compras generales (declarantes) | J9: =VLOOKUP(I9,retfuente[],3,FALSE) -> 1344573 | K9: =IF(J9>=H9,"NO APLICA","APLICA") -> NO APLICA | L9: =VLOOKUP(I9,retfuente[],4,FALSE) -> 0.025 | M9: =IF(K9="APLICA",H9*L9,0) -> 0 | N9: compras | O9: =VLOOKUP(N9,retICA[],3,FALSE) -> 471000 | P9: =IF($P$2>=H9,"NO APLICA","APLICA") -> NO APLICA | Q9: =VLOOKUP(N9,retICA[],4,FALSE) -> 0.006 | R9: =IF(P9="APLICA",H9*Q9,0) -> 0 | S9: =G9-(R9+M9) -> 364400 | U9: =G9-S9 -> 0
B10: ACEROS DUVAN | C10: 1126456991 | D10: HORMIGA | E10: 45806 | F10: 8188 | G10: 1045000 | H10: 878151 | I10: Compras generales (declarantes) | J10: =VLOOKUP(I10,retfuente[],3,FALSE) -> 1344573 | K10: =IF(J10>=H10,"NO APLICA","APLICA") -> NO APLICA | L10: =VLOOKUP(I10,retfuente[],4,FALSE) -> 0.025 | M10: =IF(K10="APLICA",H10*L10,0) -> 0 | N10: compras | O10: =VLOOKUP(N10,retICA[],3,FALSE) -> 471000 | P10: =IF($P$3>=H10,"NO APLICA","APLICA") -> APLICA | Q10: =VLOOKUP(N10,retICA[],4,FALSE) -> 0.006 | R10: =IF(P10="APLICA",H10*Q10,0) -> 5268.906 | S10: =G10-(R10+M10) -> 1039731.1 | U10: =G10-S10 -> 5268.906
B11: ACEROS DUVAN | C11: 1126456991 | D11: HORMIGA | E11: 45806 | F11: 8194 | G11: 11582254 | H11: 9941849 | I11: Compras generales (declarantes) | J11: =VLOOKUP(I11,retfuente[],3,FALSE) -> 1344573 | K11: =IF(J11>=H11,"NO APLICA","APLICA") -> APLICA | L11: =VLOOKUP(I11,retfuente[],4,FALSE) -> 0.025 | M11: =IF(K11="APLICA",H11*L11,0) -> 248546.23 | N11: compras | O11: =VLOOKUP(N11,retICA[],3,FALSE) -> 471000 | P11: =IF($P$3>=H11,"NO APLICA","APLICA") -> APLICA | Q11: =VLOOKUP(N11,retICA[],4,FALSE) -> 0.006 | R11: =IF(P11="APLICA",H11*Q11,0) -> 59651.094 | S11: =G11-(R11+M11) -> 11274057 | U11: =G11-S11 -> 308197.32
B12: ACEROS DUVAN | C12: 1126456991 | D12: HORMIGA | E12: 45805 | F12: 5937 | G12: 16000 | H12: 13445 | I12: Compras generales (declarantes) | J12: =VLOOKUP(I12,retfuente[],3,FALSE) -> 1344573 | K12: =IF(J12>=H12,"NO APLICA","APLICA") -> NO APLICA | L12: =VLOOKUP(I12,retfuente[],4,FALSE) -> 0.025 | M12: =IF(K12="APLICA",H12*L12,0) -> 0 | N12: compras | O12: =VLOOKUP(N12,retICA[],3,FALSE) -> 471000 | P12: =IF($P$3>=H12,"NO APLICA","APLICA") -> NO APLICA | Q12: =VLOOKUP(N12,retICA[],4,FALSE) -> 0.006 | R12: =IF(P12="APLICA",H12*Q12,0) -> 0 | S12: =G12-(R12+M12) -> 16000 | U12: =G12-S12 -> 0
B13: ACEROS DUVAN | C13: 1126456991 | D13: HORMIGA | E13: 45803 | F13: 5889 | G13: 32000 | H13: 26891 | I13: Compras generales (declarantes) | J13: =VLOOKUP(I13,retfuente[],3,FALSE) -> 1344573 | K13: =IF(J13>=H13,"NO APLICA","APLICA") -> NO APLICA | L13: =VLOOKUP(I13,retfuente[],4,FALSE) -> 0.025 | M13: =IF(K13="APLICA",H13*L13,0) -> 0 | N13: compras | O13: =VLOOKUP(N13,retICA[],3,FALSE) -> 471000 | P13: =IF($P$3>=H13,"NO APLICA","APLICA") -> NO APLICA | Q13: =VLOOKUP(N13,retICA[],4,FALSE) -> 0.006 | R13: =IF(P13="APLICA",H13*Q13,0) -> 0 | S13: =G13-(R13+M13) -> 32000 | U13: =G13-S13 -> 0
B14: ACEROS DUVAN | C14: 1126456991 | D14: HORMIGA | E14: 45800 | F14: 5844 | G14: 680000 | H14: 571429 | I14: Compras generales (declarantes) | J14: =VLOOKUP(I14,retfuente[],3,FALSE) -> 1344573 | K14: =IF(J14>=H14,"NO APLICA","APLICA") -> NO APLICA | L14: =VLOOKUP(I14,retfuente[],4,FALSE) -> 0.025 | M14: =IF(K14="APLICA",H14*L14,0) -> 0 | N14: compras | O14: =VLOOKUP(N14,retICA[],3,FALSE) -> 471000 | P14: =IF($P$3>=H14,"NO APLICA","APLICA") -> APLICA | Q14: =VLOOKUP(N14,retICA[],4,FALSE) -> 0.006 | R14: =IF(P14="APLICA",H14*Q14,0) -> 3428.574 | S14: =G14-(R14+M14) -> 676571.43 | U14: =G14-S14 -> 3428.574
B15: ACEROS DUVAN | C15: 1126456991 | D15: HORMIGA | E15: 45798 | F15: 7970 | G15: 60000 | H15: 50420 | I15: Compras generales (declarantes) | J15: =VLOOKUP(I15,retfuente[],3,FALSE) -> 1344573 | K15: =IF(J15>=H15,"NO APLICA","APLICA") -> NO APLICA | L15: =VLOOKUP(I15,retfuente[],4,FALSE) -> 0.025 | M15: =IF(K15="APLICA",H15*L15,0) -> 0 | N15: compras | O15: =VLOOKUP(N15,retICA[],3,FALSE) -> 471000 | P15: =IF($P$3>=H15,"NO APLICA","APLICA") -> NO APLICA | Q15: =VLOOKUP(N15,retICA[],4,FALSE) -> 0.006 | R15: =IF(P15="APLICA",H15*Q15,0) -> 0 | S15: =G15-(R15+M15) -> 60000 | U15: =G15-S15 -> 0
B16: ACEROS DUVAN | C16: 1126456991 | D16: HORMIGA | E16: 45798 | F16: 10884 | G16: 680000 | H16: 571429 | I16: Compras generales (declarantes) | J16: =VLOOKUP(I16,retfuente[],3,FALSE) -> 1344573 | K16: =IF(J16>=H16,"NO APLICA","APLICA") -> NO APLICA | L16: =VLOOKUP(I16,retfuente[],4,FALSE) -> 0.025 | M16: =IF(K16="APLICA",H16*L16,0) -> 0 | N16: compras | O16: =VLOOKUP(N16,retICA[],3,FALSE) -> 471000 | P16: =IF($P$3>=H16,"NO APLICA","APLICA") -> APLICA | Q16: =VLOOKUP(N16,retICA[],4,FALSE) -> 0.006 | R16: =IF(P16="APLICA",H16*Q16,0) -> 3428.574 | S16: =G16-(R16+M16) -> 676571.43 | U16: =G16-S16 -> 3428.574
B17: ACEROS DUVAN | C17: 1126456991 | D17: HORMIGA | E17: 45797 | F17: 7952 | G17: 52000 | H17: 43697 | I17: Compras generales (declarantes) | J17: =VLOOKUP(I17,retfuente[],3,FALSE) -> 1344573 | K17: =IF(J17>=H17,"NO APLICA","APLICA") -> NO APLICA | L17: =VLOOKUP(I17,retfuente[],4,FALSE) -> 0.025 | M17: =IF(K17="APLICA",H17*L17,0) -> 0 | N17: compras | O17: =VLOOKUP(N17,retICA[],3,FALSE) -> 471000 | P17: =IF($P$3>=H17,"NO APLICA","APLICA") -> NO APLICA | Q17: =VLOOKUP(N17,retICA[],4,FALSE) -> 0.006 | R17: =IF(P17="APLICA",H17*Q17,0) -> 0 | S17: =G17-(R17+M17) -> 52000 | U17: =G17-S17 -> 0
B18: ACEROS DUVAN | C18: 1126456991 | D18: HORMIGA | E18: 45792 | F18: 5704 | G18: 1096000 | H18: 921008 | I18: Compras generales (declarantes) | J18: =VLOOKUP(I18,retfuente[],3,FALSE) -> 1344573 | K18: =IF(J18>=H18,"NO APLICA","APLICA") -> NO APLICA | L18: =VLOOKUP(I18,retfuente[],4,FALSE) -> 0.025 | M18: =IF(K18="APLICA",H18*L18,0) -> 0 | N18: compras | O18: =VLOOKUP(N18,retICA[],3,FALSE) -> 471000 | P18: =IF($P$3>=H18,"NO APLICA","APLICA") -> APLICA | Q18: =VLOOKUP(N18,retICA[],4,FALSE) -> 0.006 | R18: =IF(P18="APLICA",H18*Q18,0) -> 5526.048 | S18: =G18-(R18+M18) -> 1090474 | U18: =G18-S18 -> 5526.048
B19: ACEROS DUVAN | C19: 1126456991 | D19: HORMIGA | E19: 45789 | F19: 7685 | G19: 31000 | H19: 26050 | I19: Compras generales (declarantes) | J19: =VLOOKUP(I19,retfuente[],3,FALSE) -> 1344573 | K19: =IF(J19>=H19,"NO APLICA","APLICA") -> NO APLICA | L19: =VLOOKUP(I19,retfuente[],4,FALSE) -> 0.025 | M19: =IF(K19="APLICA",H19*L19,0) -> 0 | N19: compras | O19: =VLOOKUP(N19,retICA[],3,FALSE) -> 471000 | P19: =IF($P$3>=H19,"NO APLICA","APLICA") -> NO APLICA | Q19: =VLOOKUP(N19,retICA[],4,FALSE) -> 0.006 | R19: =IF(P19="APLICA",H19*Q19,0) -> 0 | S19: =G19-(R19+M19) -> 31000 | U19: =G19-S19 -> 0
B20: ACEROS DUVAN | C20: 1126456991 | D20: HORMIGA | E20: 45787 | F20: 10637 | G20: 172000 | H20: 144538 | I20: Compras generales (declarantes) | J20: =VLOOKUP(I20,retfuente[],3,FALSE) -> 1344573 | K20: =IF(J20>=H20,"NO APLICA","APLICA") -> NO APLICA | L20: =VLOOKUP(I20,retfuente[],4,FALSE) -> 0.025 | M20: =IF(K20="APLICA",H20*L20,0) -> 0 | N20: compras | O20: =VLOOKUP(N20,retICA[],3,FALSE) -> 471000 | P20: =IF($P$3>=H20,"NO APLICA","APLICA") -> NO APLICA | Q20: =VLOOKUP(N20,retICA[],4,FALSE) -> 0.006 | R20: =IF(P20="APLICA",H20*Q20,0) -> 0 | S20: =G20-(R20+M20) -> 172000 | U20: =G20-S20 -> 0
B21: ACEROS DUVAN | C21: 1126456991 | D21: HORMIGA | E21: 45786 | F21: 5587 | G21: 25000 | H21: 21008 | I21: Compras generales (declarantes) | J21: =VLOOKUP(I21,retfuente[],3,FALSE) -> 1344573 | K21: =IF(J21>=H21,"NO APLICA","APLICA") -> NO APLICA | L21: =VLOOKUP(I21,retfuente[],4,FALSE) -> 0.025 | M21: =IF(K21="APLICA",H21*L21,0) -> 0 | N21: compras | O21: =VLOOKUP(N21,retICA[],3,FALSE) -> 471000 | P21: =IF($P$3>=H21,"NO APLICA","APLICA") -> NO APLICA | Q21: =VLOOKUP(N21,retICA[],4,FALSE) -> 0.006 | R21: =IF(P21="APLICA",H21*Q21,0) -> 0 | S21: =G21-(R21+M21) -> 25000 | U21: =G21-S21 -> 0
B22: SISCONT LIMITADA | C22: 814000143-8 | D22: HORMIGA | E22: 45783 | F22: 11E9215 | G22: 4567475 | H22: 3838214.3 | I22: Compras generales (declarantes) | J22: =VLOOKUP(I22,retfuente[],3,FALSE) -> 1344573 | K22: =IF(J22>=H22,"NO APLICA","APLICA") -> APLICA | L22: =VLOOKUP(I22,retfuente[],4,FALSE) -> 0.025 | M22: =IF(K22="APLICA",H22*L22,0) -> 95955.357 | N22: compras | O22: =VLOOKUP(N22,retICA[],3,FALSE) -> 471000 | P22: =IF($P$3>=H22,"NO APLICA","APLICA") -> APLICA | Q22: =VLOOKUP(N22,retICA[],4,FALSE) -> 0.006 | R22: =IF(P22="APLICA",H22*Q22,0) -> 23029.286 | S22: =G22-(R22+M22) -> 4448490.4 | U22: =G22-S22 -> 118984.64
B23: SISCONT LIMITADA | C23: 814000143-8 | D23: PRADO NORTE | E23: 45812 | F23: 01E43620 | G23: 8987423 | H23: 7552456.3 | I23: Compras generales (declarantes) | J23: =VLOOKUP(I23,retfuente[],3,FALSE) -> 1344573 | K23: =IF(J23>=H23,"NO APLICA","APLICA") -> APLICA | L23: =VLOOKUP(I23,retfuente[],4,FALSE) -> 0.025 | M23: =IF(K23="APLICA",H23*L23,0) -> 188811.41 | N23: compras | O23: =VLOOKUP(N23,retICA[],3,FALSE) -> 471000 | P23: =IF($P$3>=H23,"NO APLICA","APLICA") -> APLICA | Q23: =VLOOKUP(N23,retICA[],4,FALSE) -> 0.006 | R23: =IF(P23="APLICA",H23*Q23,0) -> 45314.738 | S23: =G23-(R23+M23) -> 8753296.9 | U23: =G23-S23 -> 234126.15
B24: ACEROS DUVAN | C24: 1126456991 | D24: HORMIGA | E24: 45819 | F24: 8528 | G24: 700000 | H24: 588235 | I24: Compras generales (declarantes) | J24: =VLOOKUP(I24,retfuente[],3,FALSE) -> 1344573 | K24: =IF(J24>=H24,"NO APLICA","APLICA") -> NO APLICA | L24: =VLOOKUP(I24,retfuente[],4,FALSE) -> 0.025 | M24: =IF(K24="APLICA",H24*L24,0) -> 0 | N24: compras | O24: =VLOOKUP(N24,retICA[],3,FALSE) -> 471000 | P24: =IF($P$3>=H24,"NO APLICA","APLICA") -> APLICA | Q24: =VLOOKUP(N24,retICA[],4,FALSE) -> 0.006 | R24: =IF(P24="APLICA",H24*Q24,0) -> 3529.41 | S24: =G24-(R24+M24) -> 696470.59 | U24: =G24-S24 -> 3529.41
B25: ACEROS DUVAN | C25: 1126456991 | D25: HORMIGA | E25: 45820 | F25: 8554 | G25: 1074000 | H25: 902521 | I25: Compras generales (declarantes) | J25: =VLOOKUP(I25,retfuente[],3,FALSE) -> 1344573 | K25: =IF(J25>=H25,"NO APLICA","APLICA") -> NO APLICA | L25: =VLOOKUP(I25,retfuente[],4,FALSE) -> 0.025 | M25: =IF(K25="APLICA",H25*L25,0) -> 0 | N25: compras | O25: =VLOOKUP(N25,retICA[],3,FALSE) -> 471000 | P25: =IF($P$3>=H25,"NO APLICA","APLICA") -> APLICA | Q25: =VLOOKUP(N25,retICA[],4,FALSE) -> 0.006 | R25: =IF(P25="APLICA",H25*Q25,0) -> 5415.126 | S25: =G25-(R25+M25) -> 1068584.9 | U25: =G25-S25 -> 5415.126
B26: SISCONT LIMITADA | C26: 814000143-8 | D26: PRADO NORTE | E26: 45814 | F26: 11E9536 | G26: 784218 | H26: 659006.72 | I26: Compras generales (declarantes) | J26: =VLOOKUP(I26,retfuente[],3,FALSE) -> 1344573 | K26: =IF(J26>=H26,"NO APLICA","APLICA") -> NO APLICA | L26: =VLOOKUP(I26,retfuente[],4,FALSE) -> 0.025 | M26: =IF(K26="APLICA",H26*L26,0) -> 0 | N26: compras | O26: =VLOOKUP(N26,retICA[],3,FALSE) -> 471000 | P26: =IF($P$3>=H26,"NO APLICA","APLICA") -> APLICA | Q26: =VLOOKUP(N26,retICA[],4,FALSE) -> 0.006 | R26: =IF(P26="APLICA",H26*Q26,0) -> 3954.0403 | S26: =G26-(R26+M26) -> 780263.96 | U26: =G26-S26 -> 3954.0403
B27: ACEROS DUVAN | C27: 1126456991 | D27: HORMIGA | E27: 45810 | F27: 8274 | G27: 2725513 | H27: 2339496 | I27: Compras generales (declarantes) | J27: =VLOOKUP(I27,retfuente[],3,FALSE) -> 1344573 | K27: =IF(J27>=H27,"NO APLICA","APLICA") -> APLICA | L27: =VLOOKUP(I27,retfuente[],4,FALSE) -> 0.025 | M27: =IF(K27="APLICA",H27*L27,0) -> 58487.4 | N27: compras | O27: =VLOOKUP(N27,retICA[],3,FALSE) -> 471000 | P27: =IF($P$3>=H27,"NO APLICA","APLICA") -> APLICA | Q27: =VLOOKUP(N27,retICA[],4,FALSE) -> 0.006 | R27: =IF(P27="APLICA",H27*Q27,0) -> 14036.976 | S27: =G27-(R27+M27) -> 2652988.6 | U27: =G27-S27 -> 72524.376
B28: EL CONSTRUCTOR | C28: 1124848579 | E28: 45826 | F28: 122154 | G28: 21363938 | H28: 17952889 | I28: Compras generales (declarantes) | J28: =VLOOKUP(I28,retfuente[],3,FALSE) -> 1344573 | K28: =IF(J28>=H28,"NO APLICA","APLICA") -> APLICA | L28: =VLOOKUP(I28,retfuente[],4,FALSE) -> 0.025 | M28: =IF(K28="APLICA",H28*L28,0) -> 448822.23 | N28: compras | O28: =VLOOKUP(N28,retICA[],3,FALSE) -> 471000 | P28: =IF($P$2>=H28,"NO APLICA","APLICA") -> APLICA | Q28: =VLOOKUP(N28,retICA[],4,FALSE) -> 0.006 | R28: =IF(P28="APLICA",H28*Q28,0) -> 107717.33 | S28: =G28-(R28+M28) -> 20807398 | U28: =G28-S28 -> 556539.56
B29: ACEROS DUVAN | C29: 1126456991 | D29: HORMIGA | E29: 45812 | F29: 6112 | G29: 20500 | H29: 17227 | I29: Compras generales (declarantes) | J29: =VLOOKUP(I29,retfuente[],3,FALSE) -> 1344573 | K29: =IF(J29>=H29,"NO APLICA","APLICA") -> NO APLICA | L29: =VLOOKUP(I29,retfuente[],4,FALSE) -> 0.025 | M29: =IF(K29="APLICA",H29*L29,0) -> 0 | N29: compras | O29: =VLOOKUP(N29,retICA[],3,FALSE) -> 471000 | P29: =IF($P$3>=H29,"NO APLICA","APLICA") -> NO APLICA | Q29: =VLOOKUP(N29,retICA[],4,FALSE) -> 0.006 | R29: =IF(P29="APLICA",H29*Q29,0) -> 0 | S29: =G29-(R29+M29) -> 20500 | U29: =G29-S29 -> 0
B30: ACEROS DUVAN | C30: 1126456991 | D30: HORMIGA | E30: 45813 | F30: 8383 | G30: 1022000 | H30: 858824 | I30: Compras generales (declarantes) | J30: =VLOOKUP(I30,retfuente[],3,FALSE) -> 1344573 | K30: =IF(J30>=H30,"NO APLICA","APLICA") -> NO APLICA | L30: =VLOOKUP(I30,retfuente[],4,FALSE) -> 0.025 | M30: =IF(K30="APLICA",H30*L30,0) -> 0 | N30: compras | O30: =VLOOKUP(N30,retICA[],3,FALSE) -> 471000 | P30: =IF($P$3>=H30,"NO APLICA","APLICA") -> APLICA | Q30: =VLOOKUP(N30,retICA[],4,FALSE) -> 0.006 | R30: =IF(P30="APLICA",H30*Q30,0) -> 5152.944 | S30: =G30-(R30+M30) -> 1016847.1 | U30: =G30-S30 -> 5152.944
B31: ACEROS DUVAN | C31: 1126456991 | D31: HORMIGA | E31: 45821 | F31: 11401 | G31: 26100 | H31: 21933 | I31: Compras generales (declarantes) | J31: =VLOOKUP(I31,retfuente[],3,FALSE) -> 1344573 | K31: =IF(J31>=H31,"NO APLICA","APLICA") -> NO APLICA | L31: =VLOOKUP(I31,retfuente[],4,FALSE) -> 0.025 | M31: =IF(K31="APLICA",H31*L31,0) -> 0 | N31: compras | O31: =VLOOKUP(N31,retICA[],3,FALSE) -> 471000 | P31: =IF($P$3>=H31,"NO APLICA","APLICA") -> NO APLICA | Q31: =VLOOKUP(N31,retICA[],4,FALSE) -> 0.006 | R31: =IF(P31="APLICA",H31*Q31,0) -> 0 | S31: =G31-(R31+M31) -> 26100 | U31: =G31-S31 -> 0
B32: ACEROS DUVAN | C32: 1126456991 | D32: HORMIGA | E32: 45825 | F32: 11448 | G32: 1069000 | H32: 898319 | I32: Compras generales (declarantes) | J32: =VLOOKUP(I32,retfuente[],3,FALSE) -> 1344573 | K32: =IF(J32>=H32,"NO APLICA","APLICA") -> NO APLICA | L32: =VLOOKUP(I32,retfuente[],4,FALSE) -> 0.025 | M32: =IF(K32="APLICA",H32*L32,0) -> 0 | N32: compras | O32: =VLOOKUP(N32,retICA[],3,FALSE) -> 471000 | P32: =IF($P$3>=H32,"NO APLICA","APLICA") -> APLICA | Q32: =VLOOKUP(N32,retICA[],4,FALSE) -> 0.006 | R32: =IF(P32="APLICA",H32*Q32,0) -> 5389.914 | S32: =G32-(R32+M32) -> 1063610.1 | U32: =G32-S32 -> 5389.914
B33: ACEROS DUVAN | C33: 1126456991 | D33: HORMIGA | E33: 45827 | F33: 8772 | G33: 1036000 | H33: 870588 | I33: Compras generales (declarantes) | J33: =VLOOKUP(I33,retfuente[],3,FALSE) -> 1344573 | K33: =IF(J33>=H33,"NO APLICA","APLICA") -> NO APLICA | L33: =VLOOKUP(I33,retfuente[],4,FALSE) -> 0.025 | M33: =IF(K33="APLICA",H33*L33,0) -> 0 | N33: compras | O33: =VLOOKUP(N33,retICA[],3,FALSE) -> 471000 | P33: =IF($P$3>=H33,"NO APLICA","APLICA") -> APLICA | Q33: =VLOOKUP(N33,retICA[],4,FALSE) -> 0.006 | R33: =IF(P33="APLICA",H33*Q33,0) -> 5223.528 | S33: =G33-(R33+M33) -> 1030776.5 | U33: =G33-S33 -> 5223.528
B34: ACEROS DUVAN | C34: 1126456991 | D34: HORMIGA | E34: 45828 | F34: 6526 | G34: 28000 | H34: 23529 | I34: Compras generales (declarantes) | J34: =VLOOKUP(I34,retfuente[],3,FALSE) -> 1344573 | K34: =IF(J34>=H34,"NO APLICA","APLICA") -> NO APLICA | L34: =VLOOKUP(I34,retfuente[],4,FALSE) -> 0.025 | M34: =IF(K34="APLICA",H34*L34,0) -> 0 | N34: compras | O34: =VLOOKUP(N34,retICA[],3,FALSE) -> 471000 | P34: =IF($P$3>=H34,"NO APLICA","APLICA") -> NO APLICA | Q34: =VLOOKUP(N34,retICA[],4,FALSE) -> 0.006 | R34: =IF(P34="APLICA",H34*Q34,0) -> 0 | S34: =G34-(R34+M34) -> 28000 | U34: =G34-S34 -> 0
B35: ACEROS DUVAN | C35: 1126456991 | D35: HORMIGA | E35: 45831 | F35: 11641 | G35: 1020109 | H35: 875630 | I35: Compras generales (declarantes) | J35: =VLOOKUP(I35,retfuente[],3,FALSE) -> 1344573 | K35: =IF(J35>=H35,"NO APLICA","APLICA") -> NO APLICA | L35: =VLOOKUP(I35,retfuente[],4,FALSE) -> 0.025 | M35: =IF(K35="APLICA",H35*L35,0) -> 0 | N35: compras | O35: =VLOOKUP(N35,retICA[],3,FALSE) -> 471000 | P35: =IF($P$3>=H35,"NO APLICA","APLICA") -> APLICA | Q35: =VLOOKUP(N35,retICA[],4,FALSE) -> 0.006 | R35: =IF(P35="APLICA",H35*Q35,0) -> 5253.78 | S35: =G35-(R35+M35) -> 1014855.2 | U35: =G35-S35 -> 5253.78
B36: ACEROS DUVAN | C36: 1126456991 | D36: HORMIGA | E36: 45836 | F36: 634 | G36: 745502 | H36: 639916 | I36: Compras generales (declarantes) | J36: =VLOOKUP(I36,retfuente[],3,FALSE) -> 1344573 | K36: =IF(J36>=H36,"NO APLICA","APLICA") -> NO APLICA | L36: =VLOOKUP(I36,retfuente[],4,FALSE) -> 0.025 | M36: =IF(K36="APLICA",H36*L36,0) -> 0 | N36: compras | O36: =VLOOKUP(N36,retICA[],3,FALSE) -> 471000 | P36: =IF($P$3>=H36,"NO APLICA","APLICA") -> APLICA | Q36: =VLOOKUP(N36,retICA[],4,FALSE) -> 0.006 | R36: =IF(P36="APLICA",H36*Q36,0) -> 3839.496 | S36: =G36-(R36+M36) -> 741662.5 | U36: =G36-S36 -> 3839.496
B37: ACEROS DUVAN | C37: 1126456991 | D37: HORMIGA | E37: 45836 | F37: 9017 | G37: 748831 | H37: 642773 | I37: Compras generales (declarantes) | J37: =VLOOKUP(I37,retfuente[],3,FALSE) -> 1344573 | K37: =IF(J37>=H37,"NO APLICA","APLICA") -> NO APLICA | L37: =VLOOKUP(I37,retfuente[],4,FALSE) -> 0.025 | M37: =IF(K37="APLICA",H37*L37,0) -> 0 | N37: compras | O37: =VLOOKUP(N37,retICA[],3,FALSE) -> 471000 | P37: =IF($P$3>=H37,"NO APLICA","APLICA") -> APLICA | Q37: =VLOOKUP(N37,retICA[],4,FALSE) -> 0.006 | R37: =IF(P37="APLICA",H37*Q37,0) -> 3856.638 | S37: =G37-(R37+M37) -> 744974.36 | U37: =G37-S37 -> 3856.638
B38: ACEROS DUVAN | C38: 1126456991 | D38: HORMIGA | E38: 45838 | F38: 9061 | G38: 3446050 | H38: 2957983 | I38: Compras generales (declarantes) | J38: =VLOOKUP(I38,retfuente[],3,FALSE) -> 1344573 | K38: =IF(J38>=H38,"NO APLICA","APLICA") -> APLICA | L38: =VLOOKUP(I38,retfuente[],4,FALSE) -> 0.025 | M38: =IF(K38="APLICA",H38*L38,0) -> 73949.575 | N38: compras | O38: =VLOOKUP(N38,retICA[],3,FALSE) -> 471000 | P38: =IF($P$3>=H38,"NO APLICA","APLICA") -> APLICA | Q38: =VLOOKUP(N38,retICA[],4,FALSE) -> 0.006 | R38: =IF(P38="APLICA",H38*Q38,0) -> 17747.898 | S38: =G38-(R38+M38) -> 3354352.5 | U38: =G38-S38 -> 91697.473
B39: ACEROS DUVAN | C39: 1126456991 | D39: HORMIGA | E39: 45846 | F39: 6955 | G39: 2778378 | H39: 2384874 | I39: Compras generales (declarantes) | J39: =VLOOKUP(I39,retfuente4[#All],3,FALSE) -> 498000 | K39: =IF(J39>=H39,"NO APLICA","APLICA") -> APLICA | L39: =VLOOKUP(I39,retfuente4[#All],4,FALSE) -> 0.025 | M39: =IF(K39="APLICA",H39*L39,0) -> 59621.85 | N39: compras | O39: =VLOOKUP(N39,RETEICAJULIO2025,3,FALSE) -> 498000 | P39: =IF($P$3>=H39,"NO APLICA","APLICA") -> APLICA | Q39: =VLOOKUP(N39,RETEICAJULIO2025,4,FALSE) -> 0.006 | R39: =IF(P39="APLICA",H39*Q39,0) -> 14309.244 | S39: =G39-(R39+M39) -> 2704446.9 | U39: =G39-S39 -> 73931.094
B40: ACEROS DUVAN | C40: 1126456991 | D40: HORMIGA | E40: 45848 | F40: 9337 | G40: 44000 | H40: 36975 | I40: Compras generales (declarantes) | J40: =VLOOKUP(I40,retfuente4[#All],3,FALSE) -> 498000 | K40: =IF(J40>=H40,"NO APLICA","APLICA") -> NO APLICA | L40: =VLOOKUP(I40,retfuente4[#All],4,FALSE) -> 0.025 | M40: =IF(K40="APLICA",H40*L40,0) -> 0 | N40: compras | O40: =VLOOKUP(N40,RETEICAJULIO2025,3,FALSE) -> 498000 | P40: =IF($P$3>=H40,"NO APLICA","APLICA") -> NO APLICA | Q40: =VLOOKUP(N40,RETEICAJULIO2025,4,FALSE) -> 0.006 | R40: =IF(P40="APLICA",H40*Q40,0) -> 0 | S40: =G40-(R40+M40) -> 44000 | U40: =G40-S40 -> 0
...

Sheet INDICADORES
B1: MALAQUITA INGENIERIA SAS
B2: NIT: 901810338-8
B3: ESTADOS FINANCIEROS A 31 DE DICIEMBRE
B5: ACTIVOS | E5: Año 1 | F5: Año 2024
C6: Activo Corriente
D7: Efectivo y equivalentes de efectivo
D8: Cuentas comerciales y otras cuentas por cobrar
D9: Inventarios
D10: Productos terminados
D11: Materias Primas y Productos en proceso | E11: 1.4769411e+08 | F11: 1.4769411e+08
D12: Materiales y respuestos
D13: Materiales en transito
D14: Inversiones
C15: Total Activos Corrientes | E15: =SUM(E6:E14) -> 1.4769411e+08 | F15: =SUM(F6:F14) -> 1.4769411e+08
C16: Activos No Corrientes
D17: Propiedad planta y equipos
D18: Propiedades de Inversiones
D19: Prestamos a empleados
D20: Inversiones
D21: Otros activos
C22: Total Activos No Corrientes | E22: =SUM(E17:E21) -> 0 | F22: =SUM(F17:F21) -> 0
C23: Total Activos | E23: =SUM(E22+E15) -> 1.4769411e+08 | F23: =SUM(F22+F15) -> 1.4769411e+08
B25: PASIVOS
C26: Pasivos Corrientes
D27: Obligaciones financieras | E27: 634152.41 | F27: 634152.41
D28: Proveedores
D29: Beneficios a empleados | E29: 900000 | F29: 900000
D30: Impuesto de renta | E30: 2951482.4 | F30: 2951482.4
D31: Dividendos por pagar
D32: Ingresos diferidos
D33: Gastos de Intereses | E33: 0 | F33: 0
C34: Total Pasivos Corrientes | E34: =SUM(E27:E33) -> 4485634.8 | F34: =SUM(F27:F33) -> 4485634.8
C35: Pasivos No Corrientes
D36: Obligaciones financieras
D37: Beneficios a empleados
D38: Impuesto de renta diferido
D39: otras provisiones
C40: Total Pasivo No Corriente | E40: =SUM(E36:E39) -> 0 | F40: =SUM(F36:F39) -> 0
C41: Total Pasivos | E41: =SUM(E40+E34) -> 4485634.8 | F41: =SUM(F40+F34) -> 4485634.8
B43: PATRIMONIO
...
